Workbook

Sheet ESRS Topics Overview
B1: Topic | C1: Sub-topic | D1: Sub-sub-topic
A2: ENVIRONMENTAL | B2: E1 Climate change
C3: E1.1 Climate change adaptation
C4: E1.2 Climate change mitigation
C5: E1.3 Energy
B6: E2 Pollution
C7: E2.1 Pollution of air
C8: E2.2 Pollution of water
C9: E2.3 Pollution of soil
C10: E2.4 Pollution of living organisms and food resources
C11: E2.5 Substances of concern
C12: E2.6 Substances of very high concern
C13: E2.7 Microplastics
B14: E3 Water and marine resources
C15: E3.1 Water | D15: Water consumption; Water withdrawals; Water discharges; Water discharges in the oceans; Extraction and use of marine resources
C16: E3.2 Marine resources
B17: E4 Biodiversity and ecosystems
C18: E4.1 Direct impact drivers of biodiversity loss | D18: Climate Change; Land-use change, fresh water-use change and sea-use change; Direct exploitation; Invasive alien species; Pollution; Others
C19: E4.2 Impacts on the state of species | D19: Examples: Species population size, Species global extinction risk
C20: E4.3 Impacts on the extent and condition of ecosystems | D20: Examples: Land degradation, Desertification, Soil sealing
C21: E4.4 Impacts and dependencies on ecosystem services
B22: E5 Circular economy
C23: E5.1 Resources inflows, including resource use
C24: E5.2 Resource outflows related to products and services
C25: E5.3 Waste
A26: SOCIAL | B26: S1 Own workforce
C27: S1.1 Working conditions | D27: Secure employment; Working time; Adequate wages; Social dialogue; Freedom of association, the existence of works councils and the information, consultation and participation rights of workers; Collective bargaining, including rate of workers covered by collective agreements; Work-life balance; Health and safety
C28: S1.2 Equal treatment and opportunities for all | D28: Gender equality and equal pay for work of equal value; Training and skills development; Employment and inclusion of persons with disabilities; Measures against violence and harassment in the workplace; Diversity
C29: S1.3 Other work-related rights | D29: Child labour; Forced labour; Adequate housing; Privacy
B30: S2 Workers in the value chain
C31: S2.1 Working conditions | D31: Secure employment; Working time; Adequate wages; Social dialogue; Freedom of association, including the existence of work councils; Collective bargaining; Work-life balance; Health and safety
C32: S2.2 Equal treatment and opportunities for all | D32: Gender equality and equal pay for work of equal value; Training and skills development; The employment and inclusion of persons with disabilities; Measures against violence and harassment in the workplace; Diversity
C33: S2.3 Other work-related rights | D33: Child labour; Forced labour; Adequate housing; Water and sanitation; Privacy
B34: S3 Affected communities
C35: S3.1 Communities’ economic, social and cultural rights | D35: Adequate housing; Adequate food; Water and sanitation; Land-related impacts; Security-related impacts
C36: S3.2 Communities’ civil and political rights | D36: Freedom of expression; Freedom of assembly; Impacts on human rights defenders
C37: S3.3 Rights of indigenous peoples | D37: Free, prior and informed consent; Self-determination; Cultural rights
B38: S4 Consumers and end-users
C39: S4.1 Information-related impacts for consumers and/or end-users | D39: Privacy; Freedom of expression; Access to (quality) information
C40: S4.2 Personal safety of consumers and/or end-users | D40: Health and safety; Security of a person; Protection of children
...

Sheet List of IROs
A1: ESRS | B1: Sustainability Aspect | C1: Impact | D1: Risk | E1: Opportunity
A2: ESRS E1
B3: E1.2 Climate change mitigation | C3: Negative: Greenhouse gas (GHG) emissions generated across the value chain (Scope 1, 2, and 3). Positive: Accelerated 25% reduction in industrial and energy-based Scope 3 emissions compared to the 2022 base year. | D3: Rising operational and regulatory costs driven by upcoming European carbon regulations (e.g., CBAM or direct carbon taxation) if supply chain decarbonization targets are missed. | E3: Enhanced competitive market positioning, brand differentiation, and improved access to sustainable financing (green bonds) by successfully decoupling economic growth from operational emissions.
A4: ESRS E5
B5: E5.2 Resource outflows related to products and services | C5: Negative: Generation of post-consumer textile waste and inefficiencies in using virgin materials for garment manufacturing. Positive: Implementation of formal circular economy and textile recycling strategies since 2023. | D5: Loss of access to key European markets due to new Extended Producer Responsibility (EPR) regulations requiring fashion brands to take financial and operational responsibility for textile waste. | E5: Capturing new conscious consumer segments and reducing raw material costs over time by scaling circular collections based on recycled textiles and closed-loop business models.
A6: ESRS S2
B7: S2.1 Working conditions | C7: Positive: Active mitigation of labor risks by maintaining 98% of tier-1 and tier-2 supplier factories under active amfori BSCI and SMETA social audits. | D7: Severe supply chain disruptions, brand reputation damage, and legal penalties if labor rights violations or non-compliance are discovered within supplier facilities. | E7: Increased supply chain resilience, higher manufacturing quality, and long-term loyalty from strategic suppliers by ensuring fair, stable, and safe working conditions.
A8: ESRS S2
B9: S2.3 Other work-related rights | C9: Positive: Drastic increase in material and fiber transparency through the full digital integration of the supply chain into the TextileGenesis traceability platform. | D9: Non-compliance penalties under the Corporate Sustainability Due Diligence Directive (CSDDD) if the company fails to provide audited, verifiable proof of ethical and forced-labor-free fiber origins. | E9: Industry leadership in the retail fashion sector by offering end-consumers complete, verifiable digital product passports and full fiber-to-store traceability.
A10: ESRS G1
B11: G1.5 Management of relationships with suppliers including payment practices | C11: Positive: Stabilization of commercial relationships and corporate governance after successfully completing the group's financial restructuring process in August 2025, operating under Lindex Group plc. | D11: Supply volatility or loss of critical suppliers if payment practices, credit terms, or purchasing contracts fail to smoothly align with the new post-restructuring corporate framework. | E11: Strengthening strategic vendor partnerships for joint investments in supply chain decarbonization and automation due to long-term financial stability gained post-restructuring.

Sheet ESG Analysis
A1: Double Materiality Assessment
A3: Impact Materiality
A4: Topic | B4: Sub-topic | C4: Impacts | D4: Impact Type | E4: Scale | F4: Scale Value | G4: Value * Likelihood | H4: Scope | I4: Scope Value | J4: Value * Likelihood | K4: Irremediable Character | L4: Value | M4: Value * Likelihood | N4: Likelihood | O4: Impact-Index | P4: Conclusion
A5: Environmental | B5: E1.2 | C5: Climate change mitigation | D5: Actual Negative | E5: High | F5: =IFERROR(VLOOKUP(E5,'Assignment Table'!$A$1:$B$6,2,FALSE),"") -> 3 | G5: =IF(OR(F5="", N5=""), "", F5*N5) -> 3 | H5: High | I5: =IFERROR(VLOOKUP(H5,'Assignment Table'!$A$1:$B$6,2,FALSE),"") -> 3 | J5: =IF(OR(I5="", N5=""), "", I5*N5) -> 3 | K5: Medium | L5: =IFERROR(VLOOKUP(K5,'Assignment Table'!$A$1:$K$6,2,FALSE),"") -> 2 | M5: =IF(OR(L5="", N5=""), "", L5*N5) -> 2 | N5: 1 | O5: =IF(OR(F5="", I5="", L5="", N5=""), "", IF(F5*I5*L5*N5=0, F5*I5*N5, F5*I5*L5*N5)) -> 18 | P5: =IF(OR(O5=""), "", IF(O5>=1.5, "yes", "no")) -> yes
A6: Environmental | B6: E5.2 | C6: Resource outflows related to products and services | D6: Potential Negative | E6: Medium | F6: =IFERROR(VLOOKUP(E6,'Assignment Table'!$A$1:$B$6,2,FALSE),"") -> 2 | G6: =IF(OR(F6="", N6=""), "", F6*N6) -> 1.2 | H6: High | I6: =IFERROR(VLOOKUP(H6,'Assignment Table'!$A$1:$B$6,2,FALSE),"") -> 3 | J6: =IF(OR(I6="", N6=""), "", I6*N6) -> 1.8 | K6: High | L6: =IFERROR(VLOOKUP(K6,'Assignment Table'!$A$1:$K$6,2,FALSE),"") -> 3 | M6: =IF(OR(L6="", N6=""), "", L6*N6) -> 1.8 | N6: 0.6 | O6: =IF(OR(F6="", I6="", L6="", N6=""), "", IF(F6*I6*L6*N6=0, F6*I6*N6, F6*I6*L6*N6)) -> 10.8 | P6: =IF(OR(O6=""), "", IF(O6>=1.5, "yes", "no")) -> yes
A7: Social | B7: S2.1 | C7: Working conditions | D7: Actual Positive | E7: High | F7: =IFERROR(VLOOKUP(E7,'Assignment Table'!$A$1:$B$6,2,FALSE),"") -> 3 | G7: =IF(OR(F7="", N7=""), "", F7*N7) -> 3 | H7: High | I7: =IFERROR(VLOOKUP(H7,'Assignment Table'!$A$1:$B$6,2,FALSE),"") -> 3 | J7: =IF(OR(I7="", N7=""), "", I7*N7) -> 3 | K7: No entry | L7: =IFERROR(VLOOKUP(K7,'Assignment Table'!$A$1:$K$6,2,FALSE),"") -> 0 | M7: =IF(OR(L7="", N7=""), "", L7*N7) -> 0 | N7: 1 | O7: =IF(OR(F7="", I7="", L7="", N7=""), "", IF(F7*I7*L7*N7=0, F7*I7*N7, F7*I7*L7*N7)) -> 9 | P7: =IF(OR(O7=""), "", IF(O7>=1.5, "yes", "no")) -> yes
A8: Social | B8: S2.3 | C8: Other work-related rights | D8: Actual Positive | E8: High | F8: =IFERROR(VLOOKUP(E8,'Assignment Table'!$A$1:$B$6,2,FALSE),"") -> 3 | G8: =IF(OR(F8="", N8=""), "", F8*N8) -> 3 | H8: Medium | I8: =IFERROR(VLOOKUP(H8,'Assignment Table'!$A$1:$B$6,2,FALSE),"") -> 2 | J8: =IF(OR(I8="", N8=""), "", I8*N8) -> 2 | K8: No entry | L8: =IFERROR(VLOOKUP(K8,'Assignment Table'!$A$1:$K$6,2,FALSE),"") -> 0 | M8: =IF(OR(L8="", N8=""), "", L8*N8) -> 0 | N8: 1 | O8: =IF(OR(F8="", I8="", L8="", N8=""), "", IF(F8*I8*L8*N8=0, F8*I8*N8, F8*I8*L8*N8)) -> 6 | P8: =IF(OR(O8=""), "", IF(O8>=1.5, "yes", "no")) -> yes
A9: Governance | B9: G1.5 | C9: Management of relationships with suppliers including payment practices | D9: Actual Positive | E9: High | F9: =IFERROR(VLOOKUP(E9,'Assignment Table'!$A$1:$B$6,2,FALSE),"") -> 3 | G9: =IF(OR(F9="", N9=""), "", F9*N9) -> 3 | H9: Medium | I9: =IFERROR(VLOOKUP(H9,'Assignment Table'!$A$1:$B$6,2,FALSE),"") -> 2 | J9: =IF(OR(I9="", N9=""), "", I9*N9) -> 2 | K9: No entry | L9: =IFERROR(VLOOKUP(K9,'Assignment Table'!$A$1:$K$6,2,FALSE),"") -> 0 | M9: =IF(OR(L9="", N9=""), "", L9*N9) -> 0 | N9: 1 | O9: =IF(OR(F9="", I9="", L9="", N9=""), "", IF(F9*I9*L9*N9=0, F9*I9*N9, F9*I9*L9*N9)) -> 6 | P9: =IF(OR(O9=""), "", IF(O9>=1.5, "yes", "no")) -> yes
A12: Financial Materiality
A13: Topic | B13: Sub-topic | C13: Risks/Opportunities | E13: Likelihood of Occurence | F13: Scale Value | H13: Potential Magnitude | I13: Potential Value | O13: R/O-Index | P13: Conclusion
A14: Environmental | B14: E1.2 | C14: E1.2 Risk | D14: N/A | E14: Possible (once every 1-2 years) | F14: =IFERROR(VLOOKUP(E14,'Assignment Table'!$H$3:$I$9,2,FALSE),"") -> 4 | G14: N/A | H14: Medium | I14: =IFERROR(VLOOKUP(H14,'Assignment Table'!$K$3:$L$9,2,FALSE),"") -> 5 | J14: N/A | K14: N/A | L14: N/A | M14: N/A | N14: N/A | O14: =IF(OR(F14="", I14=""), "", F14*I14) -> 20 | P14: =IF(OR(F14="", I14=""), "", IF(F14*I14 >=20, "yes", IF(F14*I14 <20, "no", ""))) -> yes
A15: Environmental | B15: E1.2 | C15: E1.2 Opportunity | D15: N/A | E15: Likely (1-4 times a year) | F15: =IFERROR(VLOOKUP(E15,'Assignment Table'!$H$3:$I$9,2,FALSE),"") -> 5 | G15: N/A | H15: High | I15: =IFERROR(VLOOKUP(H15,'Assignment Table'!$K$3:$L$9,2,FALSE),"") -> 6 | J15: N/A | K15: N/A | L15: N/A | M15: N/A | N15: N/A | O15: =IF(OR(F15="", I15=""), "", F15*I15) -> 30 | P15: =IF(OR(F15="", I15=""), "", IF(F15*I15 >=20, "yes", IF(F15*I15 <20, "no", ""))) -> yes
A16: Environmental | B16: E5.2 | C16: E5.2 Risk | D16: N/A | E16: Likely (1-4 times a year) | F16: =IFERROR(VLOOKUP(E16,'Assignment Table'!$H$3:$I$9,2,FALSE),"") -> 5 | G16: N/A | H16: Medium | I16: =IFERROR(VLOOKUP(H16,'Assignment Table'!$K$3:$L$9,2,FALSE),"") -> 5 | J16: N/A | K16: N/A | L16: N/A | M16: N/A | N16: N/A | O16: =IF(OR(F16="", I16=""), "", F16*I16) -> 25 | P16: =IF(OR(F16="", I16=""), "", IF(F16*I16 >=20, "yes", IF(F16*I16 <20, "no", ""))) -> yes
A17: Environmental | B17: E5.2 | C17: E5.2 Opportunity | D17: N/A | E17: Possible (once every 1-2 years) | F17: =IFERROR(VLOOKUP(E17,'Assignment Table'!$H$3:$I$9,2,FALSE),"") -> 4 | G17: N/A | H17: High | I17: =IFERROR(VLOOKUP(H17,'Assignment Table'!$K$3:$L$9,2,FALSE),"") -> 6 | J17: N/A | K17: N/A | L17: N/A | M17: N/A | N17: N/A | O17: =IF(OR(F17="", I17=""), "", F17*I17) -> 24 | P17: =IF(OR(F17="", I17=""), "", IF(F17*I17 >=20, "yes", IF(F17*I17 <20, "no", ""))) -> yes
A18: Social | B18: S2.1 | C18: S2.1 Risk | D18: N/A | E18: Possible (once every 1-2 years) | F18: =IFERROR(VLOOKUP(E18,'Assignment Table'!$H$3:$I$9,2,FALSE),"") -> 4 | G18: N/A | H18: Medium | I18: =IFERROR(VLOOKUP(H18,'Assignment Table'!$K$3:$L$9,2,FALSE),"") -> 5 | J18: N/A | K18: N/A | L18: N/A | M18: N/A | N18: N/A | O18: =IF(OR(F18="", I18=""), "", F18*I18) -> 20 | P18: =IF(OR(F18="", I18=""), "", IF(F18*I18 >=20, "yes", IF(F18*I18 <20, "no", ""))) -> yes
A19: Social | B19: S2.1 | C19: S2.1 Opportunity | D19: N/A | E19: Possible (once every 1-2 years) | F19: =IFERROR(VLOOKUP(E19,'Assignment Table'!$H$3:$I$9,2,FALSE),"") -> 4 | G19: N/A | H19: Medium | I19: =IFERROR(VLOOKUP(H19,'Assignment Table'!$K$3:$L$9,2,FALSE),"") -> 5 | J19: N/A | K19: N/A | L19: N/A | M19: N/A | N19: N/A | O19: =IF(OR(F19="", I19=""), "", F19*I19) -> 20 | P19: =IF(OR(F19="", I19=""), "", IF(F19*I19 >=20, "yes", IF(F19*I19 <20, "no", ""))) -> yes
A20: Social | B20: S2.3 | C20: S2.3 Risk | D20: N/A | E20: Likely (1-4 times a year) | F20: =IFERROR(VLOOKUP(E20,'Assignment Table'!$H$3:$I$9,2,FALSE),"") -> 5 | G20: N/A | H20: Medium | I20: =IFERROR(VLOOKUP(H20,'Assignment Table'!$K$3:$L$9,2,FALSE),"") -> 5 | J20: N/A | K20: N/A | L20: N/A | M20: N/A | N20: N/A | O20: =IF(OR(F20="", I20=""), "", F20*I20) -> 25 | P20: =IF(OR(F20="", I20=""), "", IF(F20*I20 >=20, "yes", IF(F20*I20 <20, "no", ""))) -> yes
A21: Social | B21: S2.3 | C21: S2.3 Opportunity | D21: N/A | E21: Likely (1-4 times a year) | F21: =IFERROR(VLOOKUP(E21,'Assignment Table'!$H$3:$I$9,2,FALSE),"") -> 5 | G21: N/A | H21: High | I21: =IFERROR(VLOOKUP(H21,'Assignment Table'!$K$3:$L$9,2,FALSE),"") -> 6 | J21: N/A | K21: N/A | L21: N/A | M21: N/A | N21: N/A | O21: =IF(OR(F21="", I21=""), "", F21*I21) -> 30 | P21: =IF(OR(F21="", I21=""), "", IF(F21*I21 >=20, "yes", IF(F21*I21 <20, "no", ""))) -> yes
A22: Governance | B22: G1.5 | C22: G1.5 Risk | D22: N/A | E22: Possible (once every 1-2 years) | F22: =IFERROR(VLOOKUP(E22,'Assignment Table'!$H$3:$I$9,2,FALSE),"") -> 4 | G22: N/A | H22: Medium | I22: =IFERROR(VLOOKUP(H22,'Assignment Table'!$K$3:$L$9,2,FALSE),"") -> 5 | J22: N/A | K22: N/A | L22: N/A | M22: N/A | N22: N/A | O22: =IF(OR(F22="", I22=""), "", F22*I22) -> 20 | P22: =IF(OR(F22="", I22=""), "", IF(F22*I22 >=20, "yes", IF(F22*I22 <20, "no", ""))) -> yes
A23: Governance | B23: G1.5 | C23: G1.5 Opportunity | D23: N/A | E23: Likely (1-4 times a year) | F23: =IFERROR(VLOOKUP(E23,'Assignment Table'!$H$3:$I$9,2,FALSE),"") -> 5 | G23: N/A | H23: Medium | I23: =IFERROR(VLOOKUP(H23,'Assignment Table'!$K$3:$L$9,2,FALSE),"") -> 5 | J23: N/A | K23: N/A | L23: N/A | M23: N/A | N23: N/A | O23: =IF(OR(F23="", I23=""), "", F23*I23) -> 25 | P23: =IF(OR(F23="", I23=""), "", IF(F23*I23 >=20, "yes", IF(F23*I23 <20, "no", ""))) -> yes

Sheet Assignment Table
A1: Assignment Table Impact | D1: Likelihood | F1: Impact Type | H1: Risks/Opportunities: Likelihood of Occurence | K1: Risks/Opportunities: Potential Magnitude
A2: Text | B2: Number | D2: 0.1 | F2: Actual Positive | H2: Text values | I2: Numerical values | K2: Text values | L2: Numerical values
A3: No entry | B3: 0 | D3: 0.2 | F3: Actual Negative | H3: No entry | I3: 1 | K3: No entry | L3: 1
A4: Low | B4: 1 | D4: 0.3 | F4: Potential Positive | H4: Unlikely (5 years or longer) | I4: 2 | K4: Insignificant | L4: 2
A5: Medium | B5: 2 | D5: 0.4 | F5: Potential Negative | H5: Rarely (once every 1-5 years) | I5: 3 | K5: Low | L5: 3
A6: High | B6: 3 | D6: 0.5 | H6: Possible (once every 1-2 years) | I6: 4 | K6: Moderate | L6: 4
D7: 0.6 | H7: Likely (1-4 times a year) | I7: 5 | K7: Medium | L7: 5
D8: 0.7 | H8: Often (4-12 times a year) | I8: 6 | K8: High | L8: 6
D9: 0.8 | H9: Continuously (at least once per month) | I9: 7 | K9: Very High | L9: 7
D10: 0.9
D11: 1

Sheet IM Tableau
A1: Topic | B1: Sub-topic | C1: Impacts | D1: Impact Type | E1: Scale | F1: Scale Value | G1: Value * Likelihood | H1: Scope | I1: Scope Value | J1: Value * Likelihood | K1: Irremediable Character | L1: Value | M1: Value * Likelihood | N1: Likelihood | O1: Impact-Index | P1: Conclusion | Q1: R/O-Index
A2: Environmental | B2: E1.2 | C2: Climate change mitigation | D2: Actual Negative | E2: High | F2: =IFERROR(VLOOKUP(E2,'Assignment Table'!$A$1:$B$6,2,FALSE),"") -> 3 | G2: =IF(OR(F2="", N2=""), "", F2*N2) -> 3 | H2: High | I2: =IFERROR(VLOOKUP(H2,'Assignment Table'!$A$1:$B$6,2,FALSE),"") -> 3 | J2: =IF(OR(I2="", N2=""), "", I2*N2) -> 3 | K2: Medium | L2: =IFERROR(VLOOKUP(K2,'Assignment Table'!$A$1:$K$6,2,FALSE),"") -> 2 | M2: =IF(OR(L2="", N2=""), "", L2*N2) -> 2 | N2: 1 | O2: =IF(OR(F2="", I2="", L2="", N2=""), "", IF(F2*I2*L2*N2=0, F2*I2*N2, F2*I2*L2*N2)) -> 18 | P2: =IF(OR(O2=""), "", IF(O2>=1.5, "yes", "no")) -> yes | Q2: 30
A3: Environmental | B3: E5.2 | C3: Resource outflows related to products and services | D3: Potential Negative | E3: Medium | F3: =IFERROR(VLOOKUP(E3,'Assignment Table'!$A$1:$B$6,2,FALSE),"") -> 2 | G3: =IF(OR(F3="", N3=""), "", F3*N3) -> 1.2 | H3: High | I3: =IFERROR(VLOOKUP(H3,'Assignment Table'!$A$1:$B$6,2,FALSE),"") -> 3 | J3: =IF(OR(I3="", N3=""), "", I3*N3) -> 1.8 | K3: High | L3: =IFERROR(VLOOKUP(K3,'Assignment Table'!$A$1:$K$6,2,FALSE),"") -> 3 | M3: =IF(OR(L3="", N3=""), "", L3*N3) -> 1.8 | N3: 0.6 | O3: =IF(OR(F3="", I3="", L3="", N3=""), "", IF(F3*I3*L3*N3=0, F3*I3*N3, F3*I3*L3*N3)) -> 10.8 | P3: =IF(OR(O3=""), "", IF(O3>=1.5, "yes", "no")) -> yes | Q3: 25
A4: Social | B4: S2.1 | C4: Working conditions | D4: Actual Positive | E4: High | F4: =IFERROR(VLOOKUP(E4,'Assignment Table'!$A$1:$B$6,2,FALSE),"") -> 3 | G4: =IF(OR(F4="", N4=""), "", F4*N4) -> 3 | H4: High | I4: =IFERROR(VLOOKUP(H4,'Assignment Table'!$A$1:$B$6,2,FALSE),"") -> 3 | J4: =IF(OR(I4="", N4=""), "", I4*N4) -> 3 | K4: No entry | L4: =IFERROR(VLOOKUP(K4,'Assignment Table'!$A$1:$K$6,2,FALSE),"") -> 0 | M4: =IF(OR(L4="", N4=""), "", L4*N4) -> 0 | N4: 1 | O4: =IF(OR(F4="", I4="", L4="", N4=""), "", IF(F4*I4*L4*N4=0, F4*I4*N4, F4*I4*L4*N4)) -> 9 | P4: =IF(OR(O4=""), "", IF(O4>=1.5, "yes", "no")) -> yes | Q4: 20
A5: Social | B5: S2.3 | C5: Other work-related rights | D5: Actual Positive | E5: High | F5: =IFERROR(VLOOKUP(E5,'Assignment Table'!$A$1:$B$6,2,FALSE),"") -> 3 | G5: =IF(OR(F5="", N5=""), "", F5*N5) -> 3 | H5: Medium | I5: =IFERROR(VLOOKUP(H5,'Assignment Table'!$A$1:$B$6,2,FALSE),"") -> 2 | J5: =IF(OR(I5="", N5=""), "", I5*N5) -> 2 | K5: No entry | L5: =IFERROR(VLOOKUP(K5,'Assignment Table'!$A$1:$K$6,2,FALSE),"") -> 0 | M5: =IF(OR(L5="", N5=""), "", L5*N5) -> 0 | N5: 1 | O5: =IF(OR(F5="", I5="", L5="", N5=""), "", IF(F5*I5*L5*N5=0, F5*I5*N5, F5*I5*L5*N5)) -> 6 | P5: =IF(OR(O5=""), "", IF(O5>=1.5, "yes", "no")) -> yes | Q5: 30
A6: Governance | B6: G1.5 | C6: Management of relationships with suppliers including payment practices | D6: Actual Positive | E6: High | F6: =IFERROR(VLOOKUP(E6,'Assignment Table'!$A$1:$B$6,2,FALSE),"") -> 3 | G6: =IF(OR(F6="", N6=""), "", F6*N6) -> 3 | H6: Medium | I6: =IFERROR(VLOOKUP(H6,'Assignment Table'!$A$1:$B$6,2,FALSE),"") -> 2 | J6: =IF(OR(I6="", N6=""), "", I6*N6) -> 2 | K6: No entry | L6: =IFERROR(VLOOKUP(K6,'Assignment Table'!$A$1:$K$6,2,FALSE),"") -> 0 | M6: =IF(OR(L6="", N6=""), "", L6*N6) -> 0 | N6: 1 | O6: =IF(OR(F6="", I6="", L6="", N6=""), "", IF(F6*I6*L6*N6=0, F6*I6*N6, F6*I6*L6*N6)) -> 6 | P6: =IF(OR(O6=""), "", IF(O6>=1.5, "yes", "no")) -> yes | Q6: 25

Sheet FM Tableau
A1: Topic | B1: Sub-topic | C1: Type | D1: Risks/Opportunities | F1: Likelihood of Occurence | G1: Likelihood Value | I1: Potential Magnitude | J1: Potential Value | P1: R/O-Index | Q1: Conclusion
A2: Environmental | B2: E1.2 | C2: Risk | D2: E1.2 Risk | E2: N/A | F2: Possible (once every 1-2 years) | G2: =IFERROR(VLOOKUP(F2,'Assignment Table'!$H$3:$I$9,2,FALSE),"") -> 4 | H2: N/A | I2: Medium | J2: =IFERROR(VLOOKUP(I2,'Assignment Table'!$K$3:$L$9,2,FALSE),"") -> 5 | K2: N/A | L2: N/A | M2: N/A | N2: N/A | O2: N/A | P2: =IF(OR(G2="", J2=""), "", G2*J2) -> 20 | Q2: =IF(OR(G2="", J2=""), "", IF(G2*J2 >=20, "yes", IF(G2*J2 <20, "no", ""))) -> yes
A3: Environmental | B3: E1.2 | C3: Opportunity | D3: E1.2 Opportunity | E3: N/A | F3: Likely (1-4 times a year) | G3: =IFERROR(VLOOKUP(F3,'Assignment Table'!$H$3:$I$9,2,FALSE),"") -> 5 | H3: N/A | I3: High | J3: =IFERROR(VLOOKUP(I3,'Assignment Table'!$K$3:$L$9,2,FALSE),"") -> 6 | K3: N/A | L3: N/A | M3: N/A | N3: N/A | O3: N/A | P3: =IF(OR(G3="", J3=""), "", G3*J3) -> 30 | Q3: =IF(OR(G3="", J3=""), "", IF(G3*J3 >=20, "yes", IF(G3*J3 <20, "no", ""))) -> yes
A4: Environmental | B4: E5.2 | C4: Risk | D4: E5.2 Risk | E4: N/A | F4: Likely (1-4 times a year) | G4: =IFERROR(VLOOKUP(F4,'Assignment Table'!$H$3:$I$9,2,FALSE),"") -> 5 | H4: N/A | I4: Medium | J4: =IFERROR(VLOOKUP(I4,'Assignment Table'!$K$3:$L$9,2,FALSE),"") -> 5 | K4: N/A | L4: N/A | M4: N/A | N4: N/A | O4: N/A | P4: =IF(OR(G4="", J4=""), "", G4*J4) -> 25 | Q4: =IF(OR(G4="", J4=""), "", IF(G4*J4 >=20, "yes", IF(G4*J4 <20, "no", ""))) -> yes
A5: Environmental | B5: E5.2 | C5: Opportunity | D5: E5.2 Opportunity | E5: N/A | F5: Possible (once every 1-2 years) | G5: =IFERROR(VLOOKUP(F5,'Assignment Table'!$H$3:$I$9,2,FALSE),"") -> 4 | H5: N/A | I5: High | J5: =IFERROR(VLOOKUP(I5,'Assignment Table'!$K$3:$L$9,2,FALSE),"") -> 6 | K5: N/A | L5: N/A | M5: N/A | N5: N/A | O5: N/A | P5: =IF(OR(G5="", J5=""), "", G5*J5) -> 24 | Q5: =IF(OR(G5="", J5=""), "", IF(G5*J5 >=20, "yes", IF(G5*J5 <20, "no", ""))) -> yes
A6: Social | B6: S2.1 | C6: Risk | D6: S2.1 Risk | E6: N/A | F6: Possible (once every 1-2 years) | G6: =IFERROR(VLOOKUP(F6,'Assignment Table'!$H$3:$I$9,2,FALSE),"") -> 4 | H6: N/A | I6: Medium | J6: =IFERROR(VLOOKUP(I6,'Assignment Table'!$K$3:$L$9,2,FALSE),"") -> 5 | K6: N/A | L6: N/A | M6: N/A | N6: N/A | O6: N/A | P6: =IF(OR(G6="", J6=""), "", G6*J6) -> 20 | Q6: =IF(OR(G6="", J6=""), "", IF(G6*J6 >=20, "yes", IF(G6*J6 <20, "no", ""))) -> yes
A7: Social | B7: S2.1 | C7: Opportunity | D7: S2.1 Opportunity | E7: N/A | F7: Possible (once every 1-2 years) | G7: =IFERROR(VLOOKUP(F7,'Assignment Table'!$H$3:$I$9,2,FALSE),"") -> 4 | H7: N/A | I7: Medium | J7: =IFERROR(VLOOKUP(I7,'Assignment Table'!$K$3:$L$9,2,FALSE),"") -> 5 | K7: N/A | L7: N/A | M7: N/A | N7: N/A | O7: N/A | P7: =IF(OR(G7="", J7=""), "", G7*J7) -> 20 | Q7: =IF(OR(G7="", J7=""), "", IF(G7*J7 >=20, "yes", IF(G7*J7 <20, "no", ""))) -> yes
A8: Social | B8: S2.3 | C8: Risk | D8: S2.3 Risk | E8: N/A | F8: Likely (1-4 times a year) | G8: =IFERROR(VLOOKUP(F8,'Assignment Table'!$H$3:$I$9,2,FALSE),"") -> 5 | H8: N/A | I8: Medium | J8: =IFERROR(VLOOKUP(I8,'Assignment Table'!$K$3:$L$9,2,FALSE),"") -> 5 | K8: N/A | L8: N/A | M8: N/A | N8: N/A | O8: N/A | P8: =IF(OR(G8="", J8=""), "", G8*J8) -> 25 | Q8: =IF(OR(G8="", J8=""), "", IF(G8*J8 >=20, "yes", IF(G8*J8 <20, "no", ""))) -> yes
A9: Social | B9: S2.3 | C9: Opportunity | D9: S2.3 Opportunity | E9: N/A | F9: Likely (1-4 times a year) | G9: =IFERROR(VLOOKUP(F9,'Assignment Table'!$H$3:$I$9,2,FALSE),"") -> 5 | H9: N/A | I9: High | J9: =IFERROR(VLOOKUP(I9,'Assignment Table'!$K$3:$L$9,2,FALSE),"") -> 6 | K9: N/A | L9: N/A | M9: N/A | N9: N/A | O9: N/A | P9: =IF(OR(G9="", J9=""), "", G9*J9) -> 30 | Q9: =IF(OR(G9="", J9=""), "", IF(G9*J9 >=20, "yes", IF(G9*J9 <20, "no", ""))) -> yes
A10: Governance | B10: G1.5 | C10: Risk | D10: G1.5 Risk | E10: N/A | F10: Possible (once every 1-2 years) | G10: =IFERROR(VLOOKUP(F10,'Assignment Table'!$H$3:$I$9,2,FALSE),"") -> 4 | H10: N/A | I10: Medium | J10: =IFERROR(VLOOKUP(I10,'Assignment Table'!$K$3:$L$9,2,FALSE),"") -> 5 | K10: N/A | L10: N/A | M10: N/A | N10: N/A | O10: N/A | P10: =IF(OR(G10="", J10=""), "", G10*J10) -> 20 | Q10: =IF(OR(G10="", J10=""), "", IF(G10*J10 >=20, "yes", IF(G10*J10 <20, "no", ""))) -> yes
A11: Governance | B11: G1.5 | C11: Opportunity | D11: G1.5 Opportunity | E11: N/A | F11: Likely (1-4 times a year) | G11: =IFERROR(VLOOKUP(F11,'Assignment Table'!$H$3:$I$9,2,FALSE),"") -> 5 | H11: N/A | I11: Medium | J11: =IFERROR(VLOOKUP(I11,'Assignment Table'!$K$3:$L$9,2,FALSE),"") -> 5 | K11: N/A | L11: N/A | M11: N/A | N11: N/A | O11: N/A | P11: =IF(OR(G11="", J11=""), "", G11*J11) -> 25 | Q11: =IF(OR(G11="", J11=""), "", IF(G11*J11 >=20, "yes", IF(G11*J11 <20, "no", ""))) -> yes
